<?xml version="1.0" encoding="utf-8"?>
<!-- This URDF was automatically created by SolidWorks to URDF Exporter! Originally created by Stephen Brawner (brawner@gmail.com) 
     Commit Version: 1.6.0-4-g7f85cfe  Build Version: 1.6.7995.38578
     For more information, please see http://wiki.ros.org/sw_urdf_exporter -->
<robot
  name="elegoo_car_v3_description">
  <link
    name="base_link">
    <inertial>
      <origin
        xyz="7.8956E-05 3.7218E-10 0.01835"
        rpy="0 0 0" />
      <mass
        value="0.12979" />
      <inertia
        ixx="0.00011062"
        ixy="2.9142E-12"
        ixz="-9.523E-20"
        iyy="0.00055967"
        iyz="7.1958E-20"
        izz="0.00066974" />
    </inertial>
    <visual>
      <origin
        xyz="0 0 0"
        rpy="0 0 0" />
      <geometry>
        <mesh
          filename="package://elegoo_car_v3_description/meshes/base_link.STL" />
      </geometry>
      <material
        name="">
        <color
          rgba="0.1254 0.1254 0.1254 0.9" />
      </material>
    </visual>
    <collision>
      <origin
        xyz="0 0 0"
        rpy="0 0 0" />
      <geometry>
        <mesh
          filename="package://elegoo_car_v3_description/meshes/base_link.STL" />
      </geometry>
    </collision>
  </link>
  <link
    name="support_1">
    <inertial>
      <origin
        xyz="0.0206 -0.002 0.0022054"
        rpy="0 0 0" />
      <mass
        value="0.002712" />
      <inertia
        ixx="1.3812E-07"
        ixy="-1.5174E-12"
        ixz="-1.1415E-22"
        iyy="1.4133E-07"
        iyz="2.5856E-23"
        izz="1.0916E-08" />
    </inertial>
    <visual>
      <origin
        xyz="0 0 0"
        rpy="0 0 0" />
      <geometry>
        <mesh
          filename="package://elegoo_car_v3_description/meshes/support_1.STL" />
      </geometry>
      <material
        name="">
        <color
          rgba="0.6274 0.6274 0.6274 1" />
      </material>
    </visual>
    <collision>
      <origin
        xyz="0 0 0"
        rpy="0 0 0" />
      <geometry>
        <mesh
          filename="package://elegoo_car_v3_description/meshes/support_1.STL" />
      </geometry>
    </collision>
  </link>
  <joint
    name="base_to_support_1"
    type="fixed">
    <origin
      xyz="0.040775 0.027 0.03195"
      rpy="0 0 0" />
    <parent
      link="base_link" />
    <child
      link="support_1" />
    <axis
      xyz="0 0 0" />
  </joint>
  <link
    name="motor_1">
    <inertial>
      <origin
        xyz="0.020411 0.0094 2.237E-11"
        rpy="0 0 0" />
      <mass
        value="0.031419" />
      <inertia
        ixx="2.0235E-06"
        ixy="1.6886E-14"
        ixz="-1.2125E-14"
        iyy="1.1082E-05"
        iyz="-1.6357E-14"
        izz="1.0806E-05" />
    </inertial>
    <visual>
      <origin
        xyz="0 0 0"
        rpy="0 0 0" />
      <geometry>
        <mesh
          filename="package://elegoo_car_v3_description/meshes/motor_1.STL" />
      </geometry>
      <material
        name="">
        <color
          rgba="1 1 0 1" />
      </material>
    </visual>
    <collision>
      <origin
        xyz="0 0 0"
        rpy="0 0 0" />
      <geometry>
        <mesh
          filename="package://elegoo_car_v3_description/meshes/motor_1.STL" />
      </geometry>
    </collision>
  </link>
  <joint
    name="support_to_motor_1"
    type="fixed">
    <origin
      xyz="0 0 0"
      rpy="0 0 0" />
    <parent
      link="support_1" />
    <child
      link="motor_1" />
    <axis
      xyz="0 0 0" />
  </joint>
  <link
    name="shaft_1">
    <inertial>
      <origin
        xyz="0 0.02675 3.46944695195361E-18"
        rpy="0 0 0" />
      <mass
        value="0.000688404533635746" />
      <inertia
        ixx="1.64741049166689E-07"
        ixy="-4.60027404729313E-24"
        ixz="1.12714129041243E-26"
        iyy="1.08445226689306E-09"
        iyz="-1.34835384402889E-26"
        izz="1.64741049166689E-07" />
    </inertial>
    <visual>
      <origin
        xyz="0 0 0"
        rpy="0 0 0" />
      <geometry>
        <mesh
          filename="package://elegoo_car_v3_description/meshes/shaft_1.STL" />
      </geometry>
      <material
        name="">
        <color
          rgba="1 1 1 1" />
      </material>
    </visual>
    <collision>
      <origin
        xyz="0 0 0"
        rpy="0 0 0" />
      <geometry>
        <mesh
          filename="package://elegoo_car_v3_description/meshes/shaft_1.STL" />
      </geometry>
    </collision>
  </link>
  <joint
    name="motor_to_shaft_1"
    type="continuous">
    <origin
      xyz="0 0 0"
      rpy="0 0 0" />
    <parent
      link="motor_1" />
    <child
      link="shaft_1" />
    <axis
      xyz="0 1 0" />
    <limit
      effort="0.09807"
      velocity="23" />
  </joint>
  <link
    name="ring_1">
    <inertial>
      <origin
        xyz="-3.5564E-09 0.043828 -9.0266E-10"
        rpy="0 0 0" />
      <mass
        value="0.022657" />
      <inertia
        ixx="6.7493E-06"
        ixy="4.2926E-13"
        ixz="-1.1158E-12"
        iyy="1.0295E-05"
        iyz="1.0895E-13"
        izz="6.7493E-06" />
    </inertial>
    <visual>
      <origin
        xyz="0 0 0"
        rpy="0 0 0" />
      <geometry>
        <mesh
          filename="package://elegoo_car_v3_description/meshes/ring_1.STL" />
      </geometry>
      <material
        name="">
        <color
          rgba="1 1 0 1" />
      </material>
    </visual>
    <collision>
      <origin
        xyz="0 0 0"
        rpy="0 0 0" />
      <geometry>
        <mesh
          filename="package://elegoo_car_v3_description/meshes/ring_1.STL" />
      </geometry>
    </collision>
  </link>
  <joint
    name="shaft_to_ring_1"
    type="fixed">
    <origin
      xyz="0 0 0"
      rpy="0 0 0" />
    <parent
      link="shaft_1" />
    <child
      link="ring_1" />
    <axis
      xyz="0 0 0" />
    <limit
      effort="0.07845"
      velocity="23" />
  </joint>
  <link
    name="neumatic_1">
    <inertial>
      <origin
        xyz="-2.7756E-17 0.04378 1.3878E-17"
        rpy="0 0 0" />
      <mass
        value="0.038076" />
      <inertia
        ixx="1.8373E-05"
        ixy="1.3492E-17"
        ixz="3.3873E-16"
        iyy="3.2593E-05"
        iyz="-1.1594E-17"
        izz="1.8373E-05" />
    </inertial>
    <visual>
      <origin
        xyz="0 0 0"
        rpy="0 0 0" />
      <geometry>
        <mesh
          filename="package://elegoo_car_v3_description/meshes/neumatic_1.STL" />
      </geometry>
      <material
        name="">
        <color
          rgba="0 0 0 1" />
      </material>
    </visual>
    <collision>
      <origin
        xyz="0 0 0"
        rpy="0 0 0" />
      <geometry>
        <mesh
          filename="package://elegoo_car_v3_description/meshes/neumatic_1.STL" />
      </geometry>
    </collision>
  </link>
  <joint
    name="ring_to_neumatic_1"
    type="fixed">
    <origin
      xyz="0 0 0"
      rpy="0 0 0" />
    <parent
      link="ring_1" />
    <child
      link="neumatic_1" />
    <axis
      xyz="0 0 0" />
  </joint>
  <link
    name="support_2">
    <inertial>
      <origin
        xyz="-0.0206 -0.002 0.0022054"
        rpy="0 0 0" />
      <mass
        value="0.002712" />
      <inertia
        ixx="1.3812E-07"
        ixy="-1.5174E-12"
        ixz="1.9439E-22"
        iyy="1.4133E-07"
        iyz="-3.7245E-23"
        izz="1.0916E-08" />
    </inertial>
    <visual>
      <origin
        xyz="0 0 0"
        rpy="0 0 0" />
      <geometry>
        <mesh
          filename="package://elegoo_car_v3_description/meshes/support_2.STL" />
      </geometry>
      <material
        name="">
        <color
          rgba="0.6274 0.6274 0.6274 1" />
      </material>
    </visual>
    <collision>
      <origin
        xyz="0 0 0"
        rpy="0 0 0" />
      <geometry>
        <mesh
          filename="package://elegoo_car_v3_description/meshes/support_2.STL" />
      </geometry>
    </collision>
  </link>
  <joint
    name="base_to_support_2"
    type="fixed">
    <origin
      xyz="-0.040775 0.027 0.03195"
      rpy="0 0 0" />
    <parent
      link="base_link" />
    <child
      link="support_2" />
    <axis
      xyz="0 0 0" />
  </joint>
  <link
    name="motor_2">
    <inertial>
      <origin
        xyz="-0.020411 0.0094 1.0389E-11"
        rpy="0 0 0" />
      <mass
        value="0.031419" />
      <inertia
        ixx="2.0235E-06"
        ixy="1.5445E-14"
        ixz="9.891E-15"
        iyy="1.1082E-05"
        iyz="1.8979E-14"
        izz="1.0806E-05" />
    </inertial>
    <visual>
      <origin
        xyz="0 0 0"
        rpy="0 0 0" />
      <geometry>
        <mesh
          filename="package://elegoo_car_v3_description/meshes/motor_2.STL" />
      </geometry>
      <material
        name="">
        <color
          rgba="1 1 0 1" />
      </material>
    </visual>
    <collision>
      <origin
        xyz="0 0 0"
        rpy="0 0 0" />
      <geometry>
        <mesh
          filename="package://elegoo_car_v3_description/meshes/motor_2.STL" />
      </geometry>
    </collision>
  </link>
  <joint
    name="support_to_motor_2"
    type="fixed">
    <origin
      xyz="0 0 0"
      rpy="0 0 0" />
    <parent
      link="support_2" />
    <child
      link="motor_2" />
    <axis
      xyz="0 0 0" />
  </joint>
  <link
    name="shaft_2">
    <inertial>
      <origin
        xyz="6.93889390390723E-18 0.02675 0"
        rpy="0 0 0" />
      <mass
        value="0.000688404533635747" />
      <inertia
        ixx="1.64741049166689E-07"
        ixy="2.68259366052437E-24"
        ixz="5.24715774636095E-26"
        iyy="1.08445226689306E-09"
        iyz="-4.92903635132482E-25"
        izz="1.64741049166689E-07" />
    </inertial>
    <visual>
      <origin
        xyz="0 0 0"
        rpy="0 0 0" />
      <geometry>
        <mesh
          filename="package://elegoo_car_v3_description/meshes/shaft_2.STL" />
      </geometry>
      <material
        name="">
        <color
          rgba="1 1 1 1" />
      </material>
    </visual>
    <collision>
      <origin
        xyz="0 0 0"
        rpy="0 0 0" />
      <geometry>
        <mesh
          filename="package://elegoo_car_v3_description/meshes/shaft_2.STL" />
      </geometry>
    </collision>
  </link>
  <joint
    name="motor_to_shaft_2"
    type="continuous">
    <origin
      xyz="0 0 0"
      rpy="0 0 0" />
    <parent
      link="motor_2" />
    <child
      link="shaft_2" />
    <axis
      xyz="0 -1 0" />
    <limit
      effort="0.09807"
      velocity="23" />
  </joint>
  <link
    name="ring_2">
    <inertial>
      <origin
        xyz="2.7485E-09 0.043828 -2.4307E-09"
        rpy="0 0 0" />
      <mass
        value="0.022657" />
      <inertia
        ixx="6.7493E-06"
        ixy="-3.3175E-13"
        ixz="1.4399E-12"
        iyy="1.0295E-05"
        iyz="2.9339E-13"
        izz="6.7493E-06" />
    </inertial>
    <visual>
      <origin
        xyz="0 0 0"
        rpy="0 0 0" />
      <geometry>
        <mesh
          filename="package://elegoo_car_v3_description/meshes/ring_2.STL" />
      </geometry>
      <material
        name="">
        <color
          rgba="1 1 0 1" />
      </material>
    </visual>
    <collision>
      <origin
        xyz="0 0 0"
        rpy="0 0 0" />
      <geometry>
        <mesh
          filename="package://elegoo_car_v3_description/meshes/ring_2.STL" />
      </geometry>
    </collision>
  </link>
  <joint
    name="shaft_to_ring_2"
    type="fixed">
    <origin
      xyz="0 0 0"
      rpy="0 0 0" />
    <parent
      link="shaft_2" />
    <child
      link="ring_2" />
    <axis
      xyz="0 0 0" />
    <limit
      effort="0.07845"
      velocity="23" />
  </joint>
  <link
    name="neumatic_2">
    <inertial>
      <origin
        xyz="6.9389E-18 0.04378 2.0817E-17"
        rpy="0 0 0" />
      <mass
        value="0.038076" />
      <inertia
        ixx="1.8373E-05"
        ixy="7.4015E-18"
        ixz="-2.6398E-16"
        iyy="3.2593E-05"
        iyz="-1.6176E-17"
        izz="1.8373E-05" />
    </inertial>
    <visual>
      <origin
        xyz="0 0 0"
        rpy="0 0 0" />
      <geometry>
        <mesh
          filename="package://elegoo_car_v3_description/meshes/neumatic_2.STL" />
      </geometry>
      <material
        name="">
        <color
          rgba="0 0 0 1" />
      </material>
    </visual>
    <collision>
      <origin
        xyz="0 0 0"
        rpy="0 0 0" />
      <geometry>
        <mesh
          filename="package://elegoo_car_v3_description/meshes/neumatic_2.STL" />
      </geometry>
    </collision>
  </link>
  <joint
    name="ring_to_neumatic_2"
    type="fixed">
    <origin
      xyz="0 0 0"
      rpy="0 0 0" />
    <parent
      link="ring_2" />
    <child
      link="neumatic_2" />
    <axis
      xyz="0 0 0" />
  </joint>
  <link
    name="support_3">
    <inertial>
      <origin
        xyz="-0.0206 0.002 0.0022054"
        rpy="0 0 0" />
      <mass
        value="0.002712" />
      <inertia
        ixx="1.3812E-07"
        ixy="-1.5174E-12"
        ixz="1.2242E-22"
        iyy="1.4133E-07"
        iyz="2.0553E-23"
        izz="1.0916E-08" />
    </inertial>
    <visual>
      <origin
        xyz="0 0 0"
        rpy="0 0 0" />
      <geometry>
        <mesh
          filename="package://elegoo_car_v3_description/meshes/support_3.STL" />
      </geometry>
      <material
        name="">
        <color
          rgba="0.6274 0.6274 0.6274 1" />
      </material>
    </visual>
    <collision>
      <origin
        xyz="0 0 0"
        rpy="0 0 0" />
      <geometry>
        <mesh
          filename="package://elegoo_car_v3_description/meshes/support_3.STL" />
      </geometry>
    </collision>
  </link>
  <joint
    name="base_to_support_3"
    type="fixed">
    <origin
      xyz="-0.040775 -0.027 0.03195"
      rpy="0 0 0" />
    <parent
      link="base_link" />
    <child
      link="support_3" />
    <axis
      xyz="0 0 0" />
  </joint>
  <link
    name="motor_3">
    <inertial>
      <origin
        xyz="-0.020411 -0.0094 2.237E-11"
        rpy="0 0 0" />
      <mass
        value="0.031419" />
      <inertia
        ixx="2.0235E-06"
        ixy="1.6886E-14"
        ixz="1.2125E-14"
        iyy="1.1082E-05"
        iyz="1.6357E-14"
        izz="1.0806E-05" />
    </inertial>
    <visual>
      <origin
        xyz="0 0 0"
        rpy="0 0 0" />
      <geometry>
        <mesh
          filename="package://elegoo_car_v3_description/meshes/motor_3.STL" />
      </geometry>
      <material
        name="">
        <color
          rgba="1 1 0 1" />
      </material>
    </visual>
    <collision>
      <origin
        xyz="0 0 0"
        rpy="0 0 0" />
      <geometry>
        <mesh
          filename="package://elegoo_car_v3_description/meshes/motor_3.STL" />
      </geometry>
    </collision>
  </link>
  <joint
    name="support_to_motor_3"
    type="fixed">
    <origin
      xyz="0 0 0"
      rpy="0 0 0" />
    <parent
      link="support_3" />
    <child
      link="motor_3" />
    <axis
      xyz="0 0 0" />
  </joint>
  <link
    name="shaft_3">
    <inertial>
      <origin
        xyz="6.93889390390723E-18 -0.02675 0"
        rpy="0 0 0" />
      <mass
        value="0.000688404533635747" />
      <inertia
        ixx="1.64741049166689E-07"
        ixy="-4.60027404729314E-24"
        ixz="7.87248683893647E-26"
        iyy="1.08445226689306E-09"
        iyz="1.33338562613337E-25"
        izz="1.64741049166689E-07" />
    </inertial>
    <visual>
      <origin
        xyz="0 0 0"
        rpy="0 0 0" />
      <geometry>
        <mesh
          filename="package://elegoo_car_v3_description/meshes/shaft_3.STL" />
      </geometry>
      <material
        name="">
        <color
          rgba="1 1 1 1" />
      </material>
    </visual>
    <collision>
      <origin
        xyz="0 0 0"
        rpy="0 0 0" />
      <geometry>
        <mesh
          filename="package://elegoo_car_v3_description/meshes/shaft_3.STL" />
      </geometry>
    </collision>
  </link>
  <joint
    name="motor_to_shaft_3"
    type="continuous">
    <origin
      xyz="0 0 0"
      rpy="0 0 0" />
    <parent
      link="motor_3" />
    <child
      link="shaft_3" />
    <axis
      xyz="0 -1 0" />
    <limit
      effort="0.09807"
      velocity="23" />
  </joint>
  <link
    name="ring_3">
    <inertial>
      <origin
        xyz="-3.5564E-09 -0.043828 9.0266E-10"
        rpy="0 0 0" />
      <mass
        value="0.022657" />
      <inertia
        ixx="6.7493E-06"
        ixy="-4.2926E-13"
        ixz="1.1158E-12"
        iyy="1.0295E-05"
        iyz="1.0895E-13"
        izz="6.7493E-06" />
    </inertial>
    <visual>
      <origin
        xyz="0 0 0"
        rpy="0 0 0" />
      <geometry>
        <mesh
          filename="package://elegoo_car_v3_description/meshes/ring_3.STL" />
      </geometry>
      <material
        name="">
        <color
          rgba="1 1 0 1" />
      </material>
    </visual>
    <collision>
      <origin
        xyz="0 0 0"
        rpy="0 0 0" />
      <geometry>
        <mesh
          filename="package://elegoo_car_v3_description/meshes/ring_3.STL" />
      </geometry>
    </collision>
  </link>
  <joint
    name="shaft_to_ring_3"
    type="fixed">
    <origin
      xyz="0 0 0"
      rpy="0 0 0" />
    <parent
      link="shaft_3" />
    <child
      link="ring_3" />
    <axis
      xyz="0 0 0" />
    <limit
      effort="0.07845"
      velocity="23" />
  </joint>
  <link
    name="neumatic_3">
    <inertial>
      <origin
        xyz="1.3878E-17 -0.04378 2.4286E-17"
        rpy="0 0 0" />
      <mass
        value="0.038076" />
      <inertia
        ixx="1.8373E-05"
        ixy="1.3484E-17"
        ixz="-3.3873E-16"
        iyy="3.2593E-05"
        iyz="1.1589E-17"
        izz="1.8373E-05" />
    </inertial>
    <visual>
      <origin
        xyz="0 0 0"
        rpy="0 0 0" />
      <geometry>
        <mesh
          filename="package://elegoo_car_v3_description/meshes/neumatic_3.STL" />
      </geometry>
      <material
        name="">
        <color
          rgba="0 0 0 1" />
      </material>
    </visual>
    <collision>
      <origin
        xyz="0 0 0"
        rpy="0 0 0" />
      <geometry>
        <mesh
          filename="package://elegoo_car_v3_description/meshes/neumatic_3.STL" />
      </geometry>
    </collision>
  </link>
  <joint
    name="ring_to_neumatic_3"
    type="fixed">
    <origin
      xyz="0 0 0"
      rpy="0 0 0" />
    <parent
      link="ring_3" />
    <child
      link="neumatic_3" />
    <axis
      xyz="0 0 0" />
  </joint>
  <link
    name="suppport_4">
    <inertial>
      <origin
        xyz="0.0206 0.002 0.0022054"
        rpy="0 0 0" />
      <mass
        value="0.002712" />
      <inertia
        ixx="1.3812E-07"
        ixy="-1.5174E-12"
        ixz="-1.9646E-22"
        iyy="1.4133E-07"
        iyz="2.1907E-24"
        izz="1.0916E-08" />
    </inertial>
    <visual>
      <origin
        xyz="0 0 0"
        rpy="0 0 0" />
      <geometry>
        <mesh
          filename="package://elegoo_car_v3_description/meshes/suppport_4.STL" />
      </geometry>
      <material
        name="">
        <color
          rgba="0.6274 0.6274 0.6274 1" />
      </material>
    </visual>
    <collision>
      <origin
        xyz="0 0 0"
        rpy="0 0 0" />
      <geometry>
        <mesh
          filename="package://elegoo_car_v3_description/meshes/suppport_4.STL" />
      </geometry>
    </collision>
  </link>
  <joint
    name="base_to_support_4"
    type="fixed">
    <origin
      xyz="0.040775 -0.027 0.03195"
      rpy="0 0 0" />
    <parent
      link="base_link" />
    <child
      link="suppport_4" />
    <axis
      xyz="0 0 0" />
  </joint>
  <link
    name="motor_4">
    <inertial>
      <origin
        xyz="0.020411 -0.0094 1.0389E-11"
        rpy="0 0 0" />
      <mass
        value="0.031419" />
      <inertia
        ixx="2.0235E-06"
        ixy="1.5445E-14"
        ixz="-9.891E-15"
        iyy="1.1082E-05"
        iyz="-1.8979E-14"
        izz="1.0806E-05" />
    </inertial>
    <visual>
      <origin
        xyz="0 0 0"
        rpy="0 0 0" />
      <geometry>
        <mesh
          filename="package://elegoo_car_v3_description/meshes/motor_4.STL" />
      </geometry>
      <material
        name="">
        <color
          rgba="1 1 0 1" />
      </material>
    </visual>
    <collision>
      <origin
        xyz="0 0 0"
        rpy="0 0 0" />
      <geometry>
        <mesh
          filename="package://elegoo_car_v3_description/meshes/motor_4.STL" />
      </geometry>
    </collision>
  </link>
  <joint
    name="support_to_motor_4"
    type="fixed">
    <origin
      xyz="0 0 0"
      rpy="0 0 0" />
    <parent
      link="suppport_4" />
    <child
      link="motor_4" />
    <axis
      xyz="0 0 0" />
  </joint>
  <link
    name="shaft_4">
    <inertial>
      <origin
        xyz="0 -0.02675 3.46944695195361E-18"
        rpy="0 0 0" />
      <mass
        value="0.000688404533635747" />
      <inertia
        ixx="1.64741049166689E-07"
        ixy="2.68259366052437E-24"
        ixz="-5.24715774636095E-26"
        iyy="1.08445226689306E-09"
        iyz="4.92903635132482E-25"
        izz="1.64741049166689E-07" />
    </inertial>
    <visual>
      <origin
        xyz="0 0 0"
        rpy="0 0 0" />
      <geometry>
        <mesh
          filename="package://elegoo_car_v3_description/meshes/shaft_4.STL" />
      </geometry>
      <material
        name="">
        <color
          rgba="1 1 1 1" />
      </material>
    </visual>
    <collision>
      <origin
        xyz="0 0 0"
        rpy="0 0 0" />
      <geometry>
        <mesh
          filename="package://elegoo_car_v3_description/meshes/shaft_4.STL" />
      </geometry>
    </collision>
  </link>
  <joint
    name="motor_to_shaft_4"
    type="continuous">
    <origin
      xyz="0 0 0"
      rpy="0 0 0" />
    <parent
      link="motor_4" />
    <child
      link="shaft_4" />
    <axis
      xyz="0 1 0" />
    <limit
      effort="0.09807"
      velocity="23" />
  </joint>
  <link
    name="ring_4">
    <inertial>
      <origin
        xyz="2.7485E-09 -0.043828 2.4307E-09"
        rpy="0 0 0" />
      <mass
        value="0.022657" />
      <inertia
        ixx="6.7493E-06"
        ixy="3.3175E-13"
        ixz="-1.4399E-12"
        iyy="1.0295E-05"
        iyz="2.9339E-13"
        izz="6.7493E-06" />
    </inertial>
    <visual>
      <origin
        xyz="0 0 0"
        rpy="0 0 0" />
      <geometry>
        <mesh
          filename="package://elegoo_car_v3_description/meshes/ring_4.STL" />
      </geometry>
      <material
        name="">
        <color
          rgba="1 1 0 1" />
      </material>
    </visual>
    <collision>
      <origin
        xyz="0 0 0"
        rpy="0 0 0" />
      <geometry>
        <mesh
          filename="package://elegoo_car_v3_description/meshes/ring_4.STL" />
      </geometry>
    </collision>
  </link>
  <joint
    name="shaft_to_ring_4"
    type="fixed">
    <origin
      xyz="0 0 0"
      rpy="0 0 0" />
    <parent
      link="shaft_4" />
    <child
      link="ring_4" />
    <axis
      xyz="0 0 0" />
    <limit
      effort="0.07845"
      velocity="23" />
  </joint>
  <link
    name="neumatic_4">
    <inertial>
      <origin
        xyz="0 -0.04378 2.4286E-17"
        rpy="0 0 0" />
      <mass
        value="0.038076" />
      <inertia
        ixx="1.8373E-05"
        ixy="7.4015E-18"
        ixz="2.6398E-16"
        iyy="3.2593E-05"
        iyz="1.6176E-17"
        izz="1.8373E-05" />
    </inertial>
    <visual>
      <origin
        xyz="0 0 0"
        rpy="0 0 0" />
      <geometry>
        <mesh
          filename="package://elegoo_car_v3_description/meshes/neumatic_4.STL" />
      </geometry>
      <material
        name="">
        <color
          rgba="0 0 0 1" />
      </material>
    </visual>
    <collision>
      <origin
        xyz="0 0 0"
        rpy="0 0 0" />
      <geometry>
        <mesh
          filename="package://elegoo_car_v3_description/meshes/neumatic_4.STL" />
      </geometry>
    </collision>
  </link>
  <joint
    name="ring_to_neumatic_4"
    type="fixed">
    <origin
      xyz="0 0 0"
      rpy="0 0 0" />
    <parent
      link="ring_4" />
    <child
      link="neumatic_4" />
    <axis
      xyz="0 0 0" />
  </joint>
  <link
    name="hex_support_1">
    <inertial>
      <origin
        xyz="0.08395 0.05315 0.04085"
        rpy="0 0 0" />
      <mass
        value="0.0055008" />
      <inertia
        ixx="6.5676E-07"
        ixy="-4.8058E-13"
        ixz="-1.0193E-12"
        iyy="6.5677E-07"
        iyz="1.1258E-12"
        izz="1.9767E-08" />
    </inertial>
    <visual>
      <origin
        xyz="0 0 0"
        rpy="0 0 0" />
      <geometry>
        <mesh
          filename="package://elegoo_car_v3_description/meshes/hex_support_1.STL" />
      </geometry>
      <material
        name="">
        <color
          rgba="0.6 0.6 0 1" />
      </material>
    </visual>
    <collision>
      <origin
        xyz="0 0 0"
        rpy="0 0 0" />
      <geometry>
        <mesh
          filename="package://elegoo_car_v3_description/meshes/hex_support_1.STL" />
      </geometry>
    </collision>
  </link>
  <joint
    name="base_to_hex_support_1"
    type="fixed">
    <origin
      xyz="0 0 0"
      rpy="0 0 0" />
    <parent
      link="base_link" />
    <child
      link="hex_support_1" />
    <axis
      xyz="0 0 0" />
  </joint>
  <link
    name="hex_support_2">
    <inertial>
      <origin
        xyz="2.0042E-08 0.05605 0.04085"
        rpy="0 0 0" />
      <mass
        value="0.0055008" />
      <inertia
        ixx="6.5677E-07"
        ixy="1.1972E-12"
        ixz="4.6533E-13"
        iyy="6.5677E-07"
        iyz="1.4457E-12"
        izz="1.9767E-08" />
    </inertial>
    <visual>
      <origin
        xyz="0 0 0"
        rpy="0 0 0" />
      <geometry>
        <mesh
          filename="package://elegoo_car_v3_description/meshes/hex_support_2.STL" />
      </geometry>
      <material
        name="">
        <color
          rgba="0.6 0.6 0 1" />
      </material>
    </visual>
    <collision>
      <origin
        xyz="0 0 0"
        rpy="0 0 0" />
      <geometry>
        <mesh
          filename="package://elegoo_car_v3_description/meshes/hex_support_2.STL" />
      </geometry>
    </collision>
  </link>
  <joint
    name="base_to_hex_support_2"
    type="fixed">
    <origin
      xyz="0 0 0"
      rpy="0 0 0" />
    <parent
      link="base_link" />
    <child
      link="hex_support_2" />
    <axis
      xyz="0 0 0" />
  </joint>
  <link
    name="hex_support_3">
    <inertial>
      <origin
        xyz="-0.08005 0.05555 0.04085"
        rpy="0 0 0" />
      <mass
        value="0.0055008" />
      <inertia
        ixx="6.5677E-07"
        ixy="1.1972E-12"
        ixz="4.6533E-13"
        iyy="6.5677E-07"
        iyz="1.4457E-12"
        izz="1.9767E-08" />
    </inertial>
    <visual>
      <origin
        xyz="0 0 0"
        rpy="0 0 0" />
      <geometry>
        <mesh
          filename="package://elegoo_car_v3_description/meshes/hex_support_3.STL" />
      </geometry>
      <material
        name="">
        <color
          rgba="0.6 0.6 0 1" />
      </material>
    </visual>
    <collision>
      <origin
        xyz="0 0 0"
        rpy="0 0 0" />
      <geometry>
        <mesh
          filename="package://elegoo_car_v3_description/meshes/hex_support_3.STL" />
      </geometry>
    </collision>
  </link>
  <joint
    name="base_to_hex_support_3"
    type="fixed">
    <origin
      xyz="0 0 0"
      rpy="0 0 0" />
    <parent
      link="base_link" />
    <child
      link="hex_support_3" />
    <axis
      xyz="0 0 0" />
  </joint>
  <link
    name="hex_support_4">
    <inertial>
      <origin
        xyz="-0.08005 -0.05555 0.04085"
        rpy="0 0 0" />
      <mass
        value="0.0055008" />
      <inertia
        ixx="6.5677E-07"
        ixy="-1.1972E-12"
        ixz="-4.6533E-13"
        iyy="6.5677E-07"
        iyz="1.4457E-12"
        izz="1.9767E-08" />
    </inertial>
    <visual>
      <origin
        xyz="0 0 0"
        rpy="0 0 0" />
      <geometry>
        <mesh
          filename="package://elegoo_car_v3_description/meshes/hex_support_4.STL" />
      </geometry>
      <material
        name="">
        <color
          rgba="0.6 0.6 0 1" />
      </material>
    </visual>
    <collision>
      <origin
        xyz="0 0 0"
        rpy="0 0 0" />
      <geometry>
        <mesh
          filename="package://elegoo_car_v3_description/meshes/hex_support_4.STL" />
      </geometry>
    </collision>
  </link>
  <joint
    name="base_to_hex_support_4"
    type="fixed">
    <origin
      xyz="0 0 0"
      rpy="0 0 0" />
    <parent
      link="base_link" />
    <child
      link="hex_support_4" />
    <axis
      xyz="0 0 0" />
  </joint>
  <link
    name="hex_support_5">
    <inertial>
      <origin
        xyz="2.0042E-08 -0.05605 0.04085"
        rpy="0 0 0" />
      <mass
        value="0.0055008" />
      <inertia
        ixx="6.5677E-07"
        ixy="-1.1972E-12"
        ixz="-4.6533E-13"
        iyy="6.5677E-07"
        iyz="1.4457E-12"
        izz="1.9767E-08" />
    </inertial>
    <visual>
      <origin
        xyz="0 0 0"
        rpy="0 0 0" />
      <geometry>
        <mesh
          filename="package://elegoo_car_v3_description/meshes/hex_support_5.STL" />
      </geometry>
      <material
        name="">
        <color
          rgba="0.6 0.6 0 1" />
      </material>
    </visual>
    <collision>
      <origin
        xyz="0 0 0"
        rpy="0 0 0" />
      <geometry>
        <mesh
          filename="package://elegoo_car_v3_description/meshes/hex_support_5.STL" />
      </geometry>
    </collision>
  </link>
  <joint
    name="base_to_hex_support_5"
    type="fixed">
    <origin
      xyz="0 0 0"
      rpy="0 0 0" />
    <parent
      link="base_link" />
    <child
      link="hex_support_5" />
    <axis
      xyz="0 0 0" />
  </joint>
  <link
    name="hex_support_6">
    <inertial>
      <origin
        xyz="0.08395 -0.05315 0.04085"
        rpy="0 0 0" />
      <mass
        value="0.0055008" />
      <inertia
        ixx="6.5676E-07"
        ixy="4.8058E-13"
        ixz="1.0193E-12"
        iyy="6.5677E-07"
        iyz="1.1258E-12"
        izz="1.9767E-08" />
    </inertial>
    <visual>
      <origin
        xyz="0 0 0"
        rpy="0 0 0" />
      <geometry>
        <mesh
          filename="package://elegoo_car_v3_description/meshes/hex_support_6.STL" />
      </geometry>
      <material
        name="">
        <color
          rgba="0.6 0.6 0 1" />
      </material>
    </visual>
    <collision>
      <origin
        xyz="0 0 0"
        rpy="0 0 0" />
      <geometry>
        <mesh
          filename="package://elegoo_car_v3_description/meshes/hex_support_6.STL" />
      </geometry>
    </collision>
  </link>
  <joint
    name="base_to_hex_support_6"
    type="fixed">
    <origin
      xyz="0 0 0"
      rpy="0 0 0" />
    <parent
      link="base_link" />
    <child
      link="hex_support_6" />
    <axis
      xyz="0 0 0" />
  </joint>
  <link
    name="medium_plate">
    <inertial>
      <origin
        xyz="0 0 0"
        rpy="0 0 0" />
      <mass
        value="0" />
      <inertia
        ixx="0"
        ixy="0"
        ixz="0"
        iyy="0"
        iyz="0"
        izz="0" />
    </inertial>
    <visual>
      <origin
        xyz="0 0 0"
        rpy="0 0 0" />
      <geometry>
        <mesh
          filename="package://elegoo_car_v3_description/meshes/medium_plate.STL" />
      </geometry>
      <material
        name="">
        <color
          rgba="0.1254 0.1254 0.1254 1" />
      </material>
    </visual>
    <collision>
      <origin
        xyz="0 0 0"
        rpy="0 0 0" />
      <geometry>
        <mesh
          filename="package://elegoo_car_v3_description/meshes/medium_plate.STL" />
      </geometry>
    </collision>
  </link>
  <joint
    name="base_to_medium_plate"
    type="fixed">
    <origin
      xyz="0 0 0"
      rpy="0 0 0" />
    <parent
      link="base_link" />
    <child
      link="medium_plate" />
    <axis
      xyz="0 0 0" />
  </joint>
  <link
    name="batery">
    <inertial>
      <origin
        xyz="-0.0756 -2.57123578269955E-16 0.0770886438964631"
        rpy="0 0 0" />
      <mass
        value="0.11955814092686" />
      <inertia
        ixx="6.44366513889035E-05"
        ixy="1.00749461501455E-19"
        ixz="-1.40949949997757E-22"
        iyy="3.41583566343059E-05"
        iyz="4.1091423456621E-22"
        izz="8.81872221606157E-05" />
    </inertial>
    <visual>
      <origin
        xyz="0 0 0"
        rpy="0 0 0" />
      <geometry>
        <mesh
          filename="package://elegoo_car_v3_description/meshes/batery.STL" />
      </geometry>
      <material
        name="">
        <color
          rgba="1 1 1 1" />
      </material>
    </visual>
    <collision>
      <origin
        xyz="0 0 0"
        rpy="0 0 0" />
      <geometry>
        <mesh
          filename="package://elegoo_car_v3_description/meshes/batery.STL" />
      </geometry>
    </collision>
  </link>
  <joint
    name="medium_plate_to_batey"
    type="fixed">
    <origin
      xyz="0 0 0"
      rpy="0 0 0" />
    <parent
      link="medium_plate" />
    <child
      link="batery" />
    <axis
      xyz="0 0 0" />
  </joint>
  <link
    name="arduino">
    <inertial>
      <origin
        xyz="0.0113638835773716 -0.00145317601065383 0.0691161344023989"
        rpy="0 0 0" />
      <mass
        value="0.0368263873637664" />
      <inertia
        ixx="1.61184372892082E-05"
        ixy="-1.48754035200814E-07"
        ixz="-2.26027282617775E-08"
        iyy="1.01914424989913E-05"
        iyz="-5.69833304502954E-07"
        izz="2.55986783826354E-05" />
    </inertial>
    <visual>
      <origin
        xyz="0 0 0"
        rpy="0 0 0" />
      <geometry>
        <mesh
          filename="package://elegoo_car_v3_description/meshes/arduino.STL" />
      </geometry>
      <material
        name="">
        <color
          rgba="0.529411764705882 0.549019607843137 0.549019607843137 1" />
      </material>
    </visual>
    <collision>
      <origin
        xyz="0 0 0"
        rpy="0 0 0" />
      <geometry>
        <mesh
          filename="package://elegoo_car_v3_description/meshes/arduino.STL" />
      </geometry>
    </collision>
  </link>
  <joint
    name="medium_plate_to_arduino"
    type="fixed">
    <origin
      xyz="0 0 0"
      rpy="0 0 0" />
    <parent
      link="medium_plate" />
    <child
      link="arduino" />
    <axis
      xyz="0 0 0" />
  </joint>
  <link
    name="servo_base">
    <inertial>
      <origin
        xyz="-0.00515 -0.0073693 -0.0157"
        rpy="0 0 0" />
      <mass
        value="0.0034312" />
      <inertia
        ixx="3.3119E-07"
        ixy="-3.8092E-23"
        ixz="1.5854E-24"
        iyy="5.3664E-07"
        iyz="-3.1888E-24"
        izz="8.6366E-07" />
    </inertial>
    <visual>
      <origin
        xyz="0 0 0"
        rpy="0 0 0" />
      <geometry>
        <mesh
          filename="package://elegoo_car_v3_description/meshes/servo_base.STL" />
      </geometry>
      <material
        name="">
        <color
          rgba="0.1254 0.1254 0.1254 1" />
      </material>
    </visual>
    <collision>
      <origin
        xyz="0 0 0"
        rpy="0 0 0" />
      <geometry>
        <mesh
          filename="package://elegoo_car_v3_description/meshes/servo_base.STL" />
      </geometry>
    </collision>
  </link>
  <joint
    name="medium_plate_to_servo_base"
    type="fixed">
    <origin
      xyz="0.09295 0.0001 0.0829"
      rpy="0 0 0" />
    <parent
      link="medium_plate" />
    <child
      link="servo_base" />
    <axis
      xyz="0 0 0" />
  </joint>
  <link
    name="servo">
    <inertial>
      <origin
        xyz="-0.0048466 -4.6202E-10 -0.018288"
        rpy="0 0 0" />
      <mass
        value="0.0091401" />
      <inertia
        ixx="6.3298E-07"
        ixy="-2.0846E-15"
        ixz="-3.5208E-08"
        iyy="9.5399E-07"
        iyz="3.6389E-14"
        izz="5.5455E-07" />
    </inertial>
    <visual>
      <origin
        xyz="0 0 0"
        rpy="0 0 0" />
      <geometry>
        <mesh
          filename="package://elegoo_car_v3_description/meshes/servo.STL" />
      </geometry>
      <material
        name="">
        <color
          rgba="0.2 0.2 1 0.9" />
      </material>
    </visual>
    <collision>
      <origin
        xyz="0 0 0"
        rpy="0 0 0" />
      <geometry>
        <mesh
          filename="package://elegoo_car_v3_description/meshes/servo.STL" />
      </geometry>
    </collision>
  </link>
  <joint
    name="servo_base_to_servo"
    type="fixed">
    <origin
      xyz="0 0 0"
      rpy="0 0 0" />
    <parent
      link="servo_base" />
    <child
      link="servo" />
    <axis
      xyz="0 0 0" />
  </joint>
  <link
    name="servo_shaft">
    <inertial>
      <origin
        xyz="0 2.7105E-20 -0.00325"
        rpy="0 0 0" />
      <mass
        value="0.00017405" />
      <inertia
        ixx="8.74E-10"
        ixy="1.6327E-26"
        ixz="3.1812E-26"
        iyy="8.74E-10"
        iyz="-1.5906E-26"
        izz="5.2238E-10" />
    </inertial>
    <visual>
      <origin
        xyz="0 0 0"
        rpy="0 0 0" />
      <geometry>
        <mesh
          filename="package://elegoo_car_v3_description/meshes/servo_shaft.STL" />
      </geometry>
      <material
        name="">
        <color
          rgba="0.1254 0.1254 0.1254 1" />
      </material>
    </visual>
    <collision>
      <origin
        xyz="0 0 0"
        rpy="0 0 0" />
      <geometry>
        <mesh
          filename="package://elegoo_car_v3_description/meshes/servo_shaft.STL" />
      </geometry>
    </collision>
  </link>
  <joint
    name="servo_to_shaft"
    type="continuous">
    <origin
      xyz="0 0 0"
      rpy="0 0 0" />
    <parent
      link="servo" />
    <child
      link="servo_shaft" />
    <axis
      xyz="0 0 1" />
    <limit
      lower="-1.571"
      upper="1.571"
      effort="0.0907"
      velocity="0.7" />
  </joint>
  <link
    name="ultrasonic_support">
    <inertial>
      <origin
        xyz="0.0037659 -6.4258E-07 0.016271"
        rpy="0 0 0" />
      <mass
        value="0.0052953" />
      <inertia
        ixx="1.7319E-06"
        ixy="-5.2305E-10"
        ixz="-1.0423E-07"
        iyy="8.2025E-07"
        iyz="-5.2331E-13"
        izz="9.9478E-07" />
    </inertial>
    <visual>
      <origin
        xyz="0 0 0"
        rpy="0 0 0" />
      <geometry>
        <mesh
          filename="package://elegoo_car_v3_description/meshes/ultrasonic_support.STL" />
      </geometry>
      <material
        name="">
        <color
          rgba="0.1254 0.1254 0.1254 1" />
      </material>
    </visual>
    <collision>
      <origin
        xyz="0 0 0"
        rpy="0 0 0" />
      <geometry>
        <mesh
          filename="package://elegoo_car_v3_description/meshes/ultrasonic_support.STL" />
      </geometry>
    </collision>
  </link>
  <joint
    name="servo_shaft_to_ultrasonic_support"
    type="fixed">
    <origin
      xyz="0 0 0"
      rpy="0 0 0" />
    <parent
      link="servo_shaft" />
    <child
      link="ultrasonic_support" />
    <axis
      xyz="0 0 0" />
  </joint>
  <link
    name="ultrasonic_sensor">
    <inertial>
      <origin
        xyz="0.013019 -7.4444E-06 0.022811"
        rpy="0 0 0" />
      <mass
        value="0.010497" />
      <inertia
        ixx="2.1159E-06"
        ixy="-9.5555E-10"
        ixz="2.1483E-09"
        iyy="4.4472E-07"
        iyz="-1.2284E-12"
        izz="1.9912E-06" />
    </inertial>
    <visual>
      <origin
        xyz="0 0 0"
        rpy="0 0 0" />
      <geometry>
        <mesh
          filename="package://elegoo_car_v3_description/meshes/ultrasonic_sensor.STL" />
      </geometry>
      <material
        name="">
        <color
          rgba="0.2 0.2 1 1" />
      </material>
    </visual>
    <collision>
      <origin
        xyz="0 0 0"
        rpy="0 0 0" />
      <geometry>
        <mesh
          filename="package://elegoo_car_v3_description/meshes/ultrasonic_sensor.STL" />
      </geometry>
    </collision>
  </link>
  <joint
    name="ultrasonic_support_to_ultrasonic_sensor"
    type="fixed">
    <origin
      xyz="0 0 0"
      rpy="0 0 0" />
    <parent
      link="ultrasonic_support" />
    <child
      link="ultrasonic_sensor" />
    <axis
      xyz="0 0 0" />
  </joint>
</robot>